<?xml version="1.0" ?>
<sdf version="1.5">
  <world name="default">

    <!-- A global light source -->
    <include>
      <uri>model://sun</uri>
    </include>

    <!-- A ground plane -->
    <include>
      <uri>model://ground_plane</uri>
    </include>

    <!-- The elevator car -->
    <model name="elevator">
      <pose>0 0 0.075 0 0 0</pose>
      <link name="link">
        <inertial>
          <mass>800</mass>
        </inertial>

        <collision name="floor_collision">
          <geometry>
            <box>
              <size>2.0 2.0 0.15</size>
            </box>
          </geometry>
        </collision>
        <visual name="floor_visual">
          <geometry>
            <box>
              <size>2.0 2.0 0.15</size>
            </box>
          </geometry>
        </visual>
      </link>

      <!-- <link name="door"> <pose>1.0745 -0.5 1.125 0 0 0</pose> <collision name="collision"> <geometry> <box> <size>0.08 1.0 2.25</size> </box> </geometry> </collision> <visual name="visual"> <geometry> <box> <size>0.08 1.0 2.25</size> </box>
      </geometry> </visual> </link> -->

      <link name="leftwall">
        <collision name="wall1_collision">
          <pose>0 -1.1 1.0 0 0 0</pose>
          <geometry>
            <box>
              <size>2 0.2 2</size>
            </box>
          </geometry>
        </collision>
        <visual name="wall1_visual">
          <pose>0 -1.1 1.075 0 0 0</pose>
          <geometry>
            <box>
              <size>2 0.2 2</size>
            </box>
          </geometry>
          <material>
            <script>
              <name>Gazebo/White</name>
            </script>
          </material>
        </visual>
      </link>

      <link name="rightdoor">
        <collision name="wall1_collision">
          <pose>1.0745 0.50 1.125 0 0 0</pose>
          <geometry>
            <box>
              <size>0.1 1.0 2.25</size>
            </box>
          </geometry>
        </collision>
        <visual name="wall1_visual">
          <pose>1.0745 0.50 1.125 0 0 0</pose>
          <geometry>
            <box>
              <size>0.1 1.0 2.25</size>
            </box>
          </geometry>
          <material>
            <script>
              <name>Gazebo/Red</name>
            </script>
          </material>
        </visual>
      </link>

      <link name="leftdoor">
        <collision name="wall1_collision">
          <pose>1.0745 -0.5 1.125 0 0 0</pose>
          <geometry>
            <box>
              <size>0.1 1.0 2.25</size>
            </box>
          </geometry>
        </collision>
        <visual name="wall1_visual">
          <pose>1.0745 -0.5 1.125 0 0 0</pose>
          <geometry>
            <box>
              <size>0.1 1.0 2.25</size>
            </box>
          </geometry>
          <material>
            <script>
              <name>Gazebo/White</name>
            </script>
          </material>
        </visual>
      </link>

      <joint name="ldoor" type="prismatic">
        <parent>link</parent>
        <child>leftdoor</child>
        <axis>
          <xyz>0 1 0</xyz>
          <limit>
            <lower>-1</lower>
            <upper>0</upper>
            <effort>10</effort>
          </limit>

          <dynamics>
            <damping>2</damping>
          </dynamics>
        </axis>
      </joint>

      <joint name="leftwall_joint" type="fixed">
        <pose>0 0 0 0 0 0</pose>
        <parent>link</parent>
        <child>leftwall</child>
      </joint>

      <joint name="rdoor" type="prismatic">
        <parent>link</parent>
        <child>rightdoor</child>
        <axis>
          <xyz>0 1 0</xyz>
          <limit>
            <lower>0</lower>
            <upper>1</upper>
            <effort>10</effort>
          </limit>

          <dynamics>
            <damping>2</damping>
          </dynamics>
        </axis>
      </joint>

      <joint name="lift" type="prismatic">
        <parent>world</parent>
        <child>link</child>
        <axis>
          <xyz>0 0 1</xyz>
          <limit>
            <lower>0</lower>
            <upper>10</upper>
            <effort>100000</effort>
          </limit>

          <dynamics>
            <damping>50</damping>
          </dynamics>
        </axis>
        <physics>
          <ode>
            <implicit_spring_damper>1</implicit_spring_damper>
          </ode>
        </physics>
      </joint>

      <!-- Plugin to control the elevator -->
      <plugin filename="libRosElevator.so" name="elevator_plugin">
        <lift_joint>elevator::lift</lift_joint>
        <door_joint>elevator::rdoor</door_joint>
        <left_door_joint>elevator::ldoor</left_door_joint>
        <floor_height>3.075</floor_height>

        <!-- Time the elevator door will stay open in seconds -->
        <door_wait_time>5</door_wait_time>

        <!-- This topic is used to control the elevator -->
        <topic>~/elevator</topic>
      </plugin>
    </model>

    <model name="floor0">
      <pose>2.25 0 0.075 0 0 0</pose>
      <static>true</static>
      <link name="link">
        <collision name="floor_collision">
          <geometry>
            <box>
              <size>2.0 5.0 0.15</size>
            </box>
          </geometry>
        </collision>
        <visual name="floor_visual">
          <geometry>
            <box>
              <size>2.0 5.0 0.15</size>
            </box>
          </geometry>
        </visual>
      </link>
    </model>

    <model name="floor1">
      <pose>2.25 0 3.075 0 0 0</pose>
      <static>true</static>
      <link name="link">
        <collision name="floor_collision">
          <geometry>
            <box>
              <size>2.0 5.0 0.15</size>
            </box>
          </geometry>
        </collision>
        <visual name="floor_visual">
          <geometry>
            <box>
              <size>2.0 5.0 0.15</size>
            </box>
          </geometry>
        </visual>
      </link>
    </model>

  </world>
</sdf>